2023-10-27 23:44:06,064 INFO    StreamThr :17668 [internal.py:wandb_internal():86] W&B internal server running at pid: 17668, started at: 2023-10-27 23:44:06.063139
2023-10-27 23:44:06,066 DEBUG   HandlerThread:17668 [handler.py:handle_request():146] handle_request: status
2023-10-27 23:44:06,066 INFO    WriterThread:17668 [datastore.py:open_for_write():85] open: C:\Users\Drishti\calhacks_llm\VibeMaps\wandb\run-20231027_234406-3vqt1p5t\run-3vqt1p5t.wandb
2023-10-27 23:44:06,071 DEBUG   SenderThread:17668 [sender.py:send():380] send: header
2023-10-27 23:44:06,147 DEBUG   SenderThread:17668 [sender.py:send():380] send: run
2023-10-27 23:44:06,334 ERROR   SenderThread:17668 [internal_api.py:execute():369] 403 response executing GraphQL.
2023-10-27 23:44:06,335 ERROR   SenderThread:17668 [internal_api.py:execute():370] {"errors":[{"message":"permission denied","path":["upsertBucket"],"extensions":{"code":"PERMISSION_ERROR"}}],"data":{"upsertBucket":null}}
2023-10-27 23:44:06,344 ERROR   SenderThread:17668 [sender.py:send_run():977] It appears that you do not have permission to access the requested resource. Please reach out to the project owner to grant you access. If you have the correct permissions, verify that there are no issues with your networking setup.(Error 403: Forbidden)
Traceback (most recent call last):
  File "C:\Users\Drishti\AppData\Local\Programs\PythonCodingPack\lib\site-packages\wandb\sdk\lib\retry.py", line 131, in __call__
    result = self._call_fn(*args, **kwargs)
  File "C:\Users\Drishti\AppData\Local\Programs\PythonCodingPack\lib\site-packages\wandb\sdk\internal\internal_api.py", line 366, in execute
    return self.client.execute(*args, **kwargs)  # type: ignore
  File "C:\Users\Drishti\AppData\Local\Programs\PythonCodingPack\lib\site-packages\wandb\vendor\gql-0.2.0\wandb_gql\client.py", line 52, in execute
    result = self._get_result(document, *args, **kwargs)
  File "C:\Users\Drishti\AppData\Local\Programs\PythonCodingPack\lib\site-packages\wandb\vendor\gql-0.2.0\wandb_gql\client.py", line 60, in _get_result
    return self.transport.execute(document, *args, **kwargs)
  File "C:\Users\Drishti\AppData\Local\Programs\PythonCodingPack\lib\site-packages\wandb\sdk\lib\gql_request.py", line 59, in execute
    request.raise_for_status()
  File "C:\Users\Drishti\AppData\Local\Programs\PythonCodingPack\lib\site-packages\requests\models.py", line 1021, in raise_for_status
    raise HTTPError(http_error_msg, response=self)
requests.exceptions.HTTPError: 403 Client Error: Forbidden for url: https://api.wandb.ai/graphql

During handling of the above exception, another exception occurred:

Traceback (most recent call last):
  File "C:\Users\Drishti\AppData\Local\Programs\PythonCodingPack\lib\site-packages\wandb\sdk\internal\sender.py", line 975, in send_run
    self._init_run(run, config_value_dict)
  File "C:\Users\Drishti\AppData\Local\Programs\PythonCodingPack\lib\site-packages\wandb\sdk\internal\sender.py", line 1013, in _init_run
    server_run, inserted, server_messages = self._api.upsert_run(
  File "C:\Users\Drishti\AppData\Local\Programs\PythonCodingPack\lib\site-packages\wandb\apis\normalize.py", line 73, in wrapper
    raise err
  File "C:\Users\Drishti\AppData\Local\Programs\PythonCodingPack\lib\site-packages\wandb\apis\normalize.py", line 41, in wrapper
    return func(*args, **kwargs)
  File "C:\Users\Drishti\AppData\Local\Programs\PythonCodingPack\lib\site-packages\wandb\sdk\internal\internal_api.py", line 2007, in upsert_run
    response = self.gql(
  File "C:\Users\Drishti\AppData\Local\Programs\PythonCodingPack\lib\site-packages\wandb\sdk\internal\internal_api.py", line 338, in gql
    ret = self._retry_gql(
  File "C:\Users\Drishti\AppData\Local\Programs\PythonCodingPack\lib\site-packages\wandb\sdk\lib\retry.py", line 147, in __call__
    retry_timedelta_triggered = check_retry_fn(e)
  File "C:\Users\Drishti\AppData\Local\Programs\PythonCodingPack\lib\site-packages\wandb\util.py", line 964, in check_retry_fn
    return fallback_retry_fn(e)
  File "C:\Users\Drishti\AppData\Local\Programs\PythonCodingPack\lib\site-packages\wandb\util.py", line 906, in no_retry_auth
    raise CommError(
wandb.errors.CommError: It appears that you do not have permission to access the requested resource. Please reach out to the project owner to grant you access. If you have the correct permissions, verify that there are no issues with your networking setup.(Error 403: Forbidden)
2023-10-27 23:44:06,444 DEBUG   HandlerThread:17668 [handler.py:handle_request():146] handle_request: shutdown
2023-10-27 23:44:06,445 INFO    HandlerThread:17668 [handler.py:finish():866] shutting down handler
2023-10-27 23:44:07,147 INFO    WriterThread:17668 [datastore.py:close():294] close: C:\Users\Drishti\calhacks_llm\VibeMaps\wandb\run-20231027_234406-3vqt1p5t\run-3vqt1p5t.wandb
2023-10-27 23:44:07,367 INFO    SenderThread:17668 [sender.py:finish():1534] shutting down sender
